2024-10-03 15:45:37,401 ERROR: Error processing video: in user code:

    File "C:\Users\aswal\AppData\Local\Programs\Python\Python39\lib\site-packages\keras\engine\training.py", line 1845, in predict_function  *
        return step_function(self, iterator)
    File "C:\Users\aswal\AppData\Local\Programs\Python\Python39\lib\site-packages\keras\engine\training.py", line 1834, in step_function  **
        outputs = model.distribute_strategy.run(run_step, args=(data,))
    File "C:\Users\aswal\AppData\Local\Programs\Python\Python39\lib\site-packages\keras\engine\training.py", line 1823, in run_step  **
        outputs = model.predict_step(data)
    File "C:\Users\aswal\AppData\Local\Programs\Python\Python39\lib\site-packages\keras\engine\training.py", line 1791, in predict_step
        return self(x, training=False)
    File "C:\Users\aswal\AppData\Local\Programs\Python\Python39\lib\site-packages\keras\utils\traceback_utils.py", line 67, in error_handler
        raise e.with_traceback(filtered_tb) from None
    File "C:\Users\aswal\AppData\Local\Programs\Python\Python39\lib\site-packages\keras\engine\input_spec.py", line 264, in assert_input_compatibility
        raise ValueError(f'Input {input_index} of layer "{layer_name}" is '

    ValueError: Input 0 of layer "sequential" is incompatible with the layer: expected shape=(None, 64, 64, 3), found shape=(None, 224, 224, 3)
 [in C:\Users\aswal\deep_fake\app.py:121]
2024-10-03 15:46:35,384 INFO: Deepfake detection startup [in C:\Users\aswal\deep_fake\app.py:43]
2024-10-03 15:46:44,428 INFO: MongoDB connected successfully [in C:\Users\aswal\deep_fake\app.py:51]
2024-10-03 15:46:45,553 INFO: New model created and saved successfully [in C:\Users\aswal\deep_fake\app.py:63]
2024-10-03 15:46:45,636 INFO: Model loaded successfully [in C:\Users\aswal\deep_fake\app.py:72]
2024-10-03 15:47:20,159 INFO: Processed video: 2db170ef-606b-4726-90d0-64c29d519fe42024-05-14_07-33-57_UTC.mp4, Result: Genuine [in C:\Users\aswal\deep_fake\app.py:114]
2024-10-03 15:47:43,376 INFO: Processed video: f0378e86-0306-484e-892f-348e325d31002024-07-06_12-48-02_UTC.mp4, Result: Genuine [in C:\Users\aswal\deep_fake\app.py:114]
2024-10-03 15:47:50,062 INFO: Processed video: 9351ccdb-a035-4095-86ee-e3fb6446e6dd2024-07-06_12-48-02_UTC.mp4, Result: Genuine [in C:\Users\aswal\deep_fake\app.py:114]
2024-10-03 15:48:03,821 INFO: Processed video: 5c205034-07df-450e-835e-f22793a943882024-03-10_21.23.36_3320764317580608459_54176457297.mp4, Result: Genuine [in C:\Users\aswal\deep_fake\app.py:114]
2024-10-03 15:49:30,243 INFO: Processed video: 45c6f90c-543c-4e7a-b1f3-47a9826d92eb2024-08-08_04-51-41_UTC.mp4, Result: Genuine [in C:\Users\aswal\deep_fake\app.py:114]
2024-10-03 15:49:38,805 INFO: Processed video: 2d35998e-fd99-4270-8777-a7a3b69281082024-08-08_04-51-41_UTC.mp4, Result: Genuine [in C:\Users\aswal\deep_fake\app.py:114]
2024-10-03 15:52:35,088 INFO: Processed video: ff8f7ca6-221f-4a08-ba7c-472e2efbeb47aagfhgtpmv.mp4, Result: Genuine [in C:\Users\aswal\deep_fake\app.py:114]
2024-10-03 15:52:41,025 INFO: Processed video: 1967d0f9-d140-4bd3-9b7a-17f369f85029aagfhgtpmv.mp4, Result: Genuine [in C:\Users\aswal\deep_fake\app.py:114]
2024-10-03 15:56:19,642 INFO: Processed video: 6786d817-285e-4989-a9aa-9c8c3a080ffbaagfhgtpmv.mp4, Result: Genuine [in C:\Users\aswal\deep_fake\app.py:114]
2024-10-03 15:57:57,127 INFO: Deepfake detection startup [in C:\Users\aswal\deep_fake\app.py:43]
2024-10-03 15:58:02,099 INFO: MongoDB connected successfully [in C:\Users\aswal\deep_fake\app.py:51]
2024-10-03 15:58:03,316 INFO: New model created and saved successfully [in C:\Users\aswal\deep_fake\app.py:63]
2024-10-03 15:58:03,444 ERROR: Failed to load model: Unrecognized keyword arguments: ['batch_shape'] [in C:\Users\aswal\deep_fake\app.py:74]
2024-10-03 16:26:29,173 INFO: Deepfake detection startup [in C:\Users\aswal\deep_fake\app.py:43]
2024-10-03 16:26:48,302 INFO: MongoDB connected successfully [in C:\Users\aswal\deep_fake\app.py:51]
2024-10-03 16:26:52,355 ERROR: Failed to load model: Unrecognized keyword arguments: ['batch_shape'] [in C:\Users\aswal\deep_fake\app.py:63]
2024-10-03 16:42:12,984 INFO: Deepfake detection startup [in C:\Users\aswal\deep_fake\app.py:42]
2024-10-03 16:42:30,012 INFO: MongoDB connected successfully [in C:\Users\aswal\deep_fake\app.py:50]
2024-10-03 16:42:39,351 ERROR: Failed to load model: Layer count mismatch when loading weights from file. Model expected 2 layers, found 11 saved layers. [in C:\Users\aswal\deep_fake\app.py:70]
2024-10-03 16:49:32,518 INFO: Deepfake detection startup [in C:\Users\aswal\deep_fake\app.py:42]
2024-10-03 16:49:42,631 INFO: MongoDB connected successfully [in C:\Users\aswal\deep_fake\app.py:50]
2024-10-03 16:49:45,758 ERROR: Failed to load model: Layer count mismatch when loading weights from file. Model expected 3 layers, found 11 saved layers. [in C:\Users\aswal\deep_fake\app.py:71]
2024-10-03 16:58:20,708 INFO: Deepfake detection startup [in C:\Users\aswal\deep_fake\app.py:40]
2024-10-03 16:58:31,892 INFO: MongoDB connected successfully [in C:\Users\aswal\deep_fake\app.py:48]
2024-10-03 16:58:33,652 ERROR: Failed to load model: Unrecognized keyword arguments: ['batch_shape'] [in C:\Users\aswal\deep_fake\app.py:58]
2024-10-03 16:59:51,653 INFO: Deepfake detection startup [in C:\Users\aswal\deep_fake\app.py:40]
2024-10-03 16:59:57,048 INFO: MongoDB connected successfully [in C:\Users\aswal\deep_fake\app.py:48]
2024-10-03 16:59:57,072 ERROR: Failed to load model: Unrecognized keyword arguments: ['batch_shape'] [in C:\Users\aswal\deep_fake\app.py:58]
2024-10-03 17:12:18,323 INFO: Deepfake detection startup [in C:\Users\aswal\deep_fake\app.py:41]
2024-10-03 17:12:32,363 INFO: MongoDB connected successfully [in C:\Users\aswal\deep_fake\app.py:49]
2024-10-03 17:12:35,598 ERROR: Failed to load model: Unrecognized keyword arguments: ['batch_shape'] [in C:\Users\aswal\deep_fake\app.py:59]
2024-10-03 17:21:29,615 INFO: Deepfake detection startup [in C:\Users\aswal\deep_fake\app.py:41]
2024-10-03 17:21:37,017 INFO: MongoDB connected successfully [in C:\Users\aswal\deep_fake\app.py:49]
2024-10-03 17:21:38,589 ERROR: Failed to load model: Unrecognized keyword arguments: ['batch_shape'] [in C:\Users\aswal\deep_fake\app.py:59]
2024-10-03 17:50:54,001 INFO: Deepfake detection startup [in C:\Users\aswal\deep_fake\app.py:41]
2024-10-03 17:51:05,842 INFO: MongoDB connected successfully [in C:\Users\aswal\deep_fake\app.py:49]
2024-10-03 17:51:08,684 ERROR: Failed to load model: Unrecognized keyword arguments: ['batch_shape'] [in C:\Users\aswal\deep_fake\app.py:59]
2024-10-03 18:01:36,843 INFO: Deepfake detection startup [in C:\Users\aswal\deep_fake\app.py:41]
2024-10-03 18:01:45,547 INFO: MongoDB connected successfully [in C:\Users\aswal\deep_fake\app.py:49]
2024-10-03 18:01:48,368 ERROR: Failed to load model: Unrecognized keyword arguments: ['batch_shape'] [in C:\Users\aswal\deep_fake\app.py:63]
2024-10-03 18:43:31,556 INFO: Deepfake detection startup [in C:\Users\aswal\deep_fake\app.py:41]
2024-10-03 18:43:36,566 INFO: MongoDB connected successfully [in C:\Users\aswal\deep_fake\app.py:49]
2024-10-03 18:43:41,641 ERROR: Failed to load model: ('Unrecognized keyword arguments:', dict_keys(['batch_shape'])) [in C:\Users\aswal\deep_fake\app.py:63]
2024-10-03 18:53:38,946 INFO: Deepfake detection startup [in C:\Users\aswal\deep_fake\app.py:41]
2024-10-03 18:53:48,578 INFO: MongoDB connected successfully [in C:\Users\aswal\deep_fake\app.py:49]
2024-10-03 18:53:51,753 ERROR: Failed to load model: ('Unrecognized keyword arguments:', dict_keys(['batch_shape'])) [in C:\Users\aswal\deep_fake\app.py:63]
2024-10-03 19:33:18,140 INFO: Deepfake detection startup [in C:\Users\aswal\deep_fake\app.py:41]
2024-10-03 19:33:20,601 ERROR: MongoDB connection failed: All nameservers failed to answer the query _mongodb._tcp.cluster0.f04xs.mongodb.net. IN SRV:  [in C:\Users\aswal\deep_fake\app.py:51]
2024-10-03 23:48:09,336 INFO: Deepfake detection startup [in C:\Users\aswal\deep_fake\app.py:41]
2024-10-03 23:48:12,834 INFO: MongoDB connected successfully [in C:\Users\aswal\deep_fake\app.py:49]
2024-10-03 23:48:15,831 ERROR: Failed to load model: Unrecognized keyword arguments: ['batch_shape'] [in C:\Users\aswal\deep_fake\app.py:63]
2024-10-04 00:01:49,252 INFO: Deepfake detection startup [in C:\Users\aswal\deep_fake\app.py:42]
2024-10-04 00:01:49,996 INFO: MongoDB connected successfully [in C:\Users\aswal\deep_fake\app.py:50]
2024-10-04 00:01:50,078 ERROR: Failed to load model: Unrecognized keyword arguments: ['batch_shape'] [in C:\Users\aswal\deep_fake\app.py:70]
2024-10-04 18:51:16,993 INFO: Deepfake detection startup [in C:\Users\aswal\deep_fake\app.py:42]
2024-10-04 18:51:19,890 INFO: MongoDB connected successfully [in C:\Users\aswal\deep_fake\app.py:50]
2024-10-04 18:51:26,609 INFO: Model loaded successfully [in C:\Users\aswal\deep_fake\app.py:68]
2024-10-04 19:00:33,406 INFO: Deepfake detection startup [in C:\Users\aswal\deep_fake\app.py:42]
2024-10-04 19:00:35,083 INFO: MongoDB connected successfully [in C:\Users\aswal\deep_fake\app.py:50]
2024-10-04 19:00:36,303 INFO: Model loaded successfully [in C:\Users\aswal\deep_fake\app.py:67]
2024-10-04 19:15:05,612 INFO: Deepfake detection startup [in C:\Users\aswal\deep_fake\app.py:42]
2024-10-04 19:15:07,587 INFO: MongoDB connected successfully [in C:\Users\aswal\deep_fake\app.py:50]
2024-10-04 19:15:09,684 INFO: Model loaded successfully [in C:\Users\aswal\deep_fake\app.py:67]
2024-10-04 19:50:07,970 INFO: Deepfake detection startup [in C:\Users\aswal\deep_fake\app.py:42]
2024-10-04 19:50:10,384 INFO: MongoDB connected successfully [in C:\Users\aswal\deep_fake\app.py:50]
2024-10-04 19:50:11,388 INFO: Model loaded successfully [in C:\Users\aswal\deep_fake\app.py:67]
2024-10-04 19:52:06,774 INFO: Deepfake detection startup [in C:\Users\aswal\deep_fake\app.py:42]
2024-10-04 19:52:07,606 INFO: MongoDB connected successfully [in C:\Users\aswal\deep_fake\app.py:50]
2024-10-04 19:52:08,120 INFO: Model loaded successfully [in C:\Users\aswal\deep_fake\app.py:67]
