2024-10-03 13:11:03,296 INFO: Deepfake detection startup [in C:\Users\aswal\deep_fake\app.py:40]
2024-10-03 13:11:12,258 ERROR: MongoDB connection failed: All nameservers failed to answer the query _mongodb._tcp.cluster0.0pfhp.mongodb.net. IN SRV:  [in C:\Users\aswal\deep_fake\app.py:50]
2024-10-03 13:27:15,429 INFO: Deepfake detection startup [in C:\Users\aswal\deep_fake\app.py:40]
2024-10-03 13:27:19,543 ERROR: MongoDB connection failed: All nameservers failed to answer the query _mongodb._tcp.cluster0.0pfhp.mongodb.net. IN SRV:  [in C:\Users\aswal\deep_fake\app.py:50]
2024-10-03 13:49:13,361 INFO: Deepfake detection startup [in C:\Users\aswal\deep_fake\app.py:40]
2024-10-03 13:49:18,320 ERROR: MongoDB connection failed: All nameservers failed to answer the query _mongodb._tcp.cluster0.0pfhp.mongodb.net. IN SRV:  [in C:\Users\aswal\deep_fake\app.py:50]
2024-10-03 13:53:35,098 INFO: Deepfake detection startup [in C:\Users\aswal\deep_fake\app.py:40]
2024-10-03 13:53:35,100 ERROR: MongoDB connection failed: Invalid URI scheme: URI must begin with 'mongodb://' or 'mongodb+srv://' [in C:\Users\aswal\deep_fake\app.py:50]
2024-10-03 13:57:32,303 INFO: Deepfake detection startup [in C:\Users\aswal\deep_fake\app.py:40]
2024-10-03 13:57:32,324 ERROR: MongoDB connection failed: Invalid URI scheme: URI must begin with 'mongodb://' or 'mongodb+srv://' [in C:\Users\aswal\deep_fake\app.py:50]
2024-10-03 14:12:38,100 INFO: Deepfake detection startup [in C:\Users\aswal\deep_fake\app.py:40]
2024-10-03 14:12:38,121 ERROR: MongoDB connection failed: Invalid URI scheme: URI must begin with 'mongodb://' or 'mongodb+srv://' [in C:\Users\aswal\deep_fake\app.py:50]
2024-10-03 14:29:51,137 INFO: Deepfake detection startup [in C:\Users\aswal\deep_fake\app.py:40]
2024-10-03 14:29:54,819 ERROR: MongoDB connection failed: All nameservers failed to answer the query _mongodb._tcp.cluster0.0pfhp.mongodb.net. IN SRV:  [in C:\Users\aswal\deep_fake\app.py:50]
2024-10-03 14:32:06,799 INFO: Deepfake detection startup [in C:\Users\aswal\deep_fake\app.py:40]
2024-10-03 14:32:06,801 ERROR: MongoDB connection failed: 'mongodb+srv://aswalh0707:l9h4BplwLxHIywm9@cluster0.0pfhp.mongodb.net/deepfake-detection?retryWrites=true&w=majority&appName=Cluster0' [in C:\Users\aswal\deep_fake\app.py:50]
2024-10-03 14:54:05,775 INFO: Deepfake detection startup [in C:\Users\aswal\deep_fake\app.py:40]
2024-10-03 14:54:09,594 ERROR: MongoDB connection failed: All nameservers failed to answer the query _mongodb._tcp.cluster0.f04xs.mongodb.net. IN SRV:  [in C:\Users\aswal\deep_fake\app.py:50]
2024-10-03 15:03:38,220 INFO: Deepfake detection startup [in C:\Users\aswal\deep_fake\app.py:40]
2024-10-03 15:03:47,379 ERROR: MongoDB connection failed: bad auth : authentication failed, full error: {'ok': 0, 'errmsg': 'bad auth : authentication failed', 'code': 8000, 'codeName': 'AtlasError'} [in C:\Users\aswal\deep_fake\app.py:50]
2024-10-03 15:17:43,102 INFO: Deepfake detection startup [in C:\Users\aswal\deep_fake\app.py:40]
2024-10-03 15:17:54,233 ERROR: MongoDB connection failed: bad auth : authentication failed, full error: {'ok': 0, 'errmsg': 'bad auth : authentication failed', 'code': 8000, 'codeName': 'AtlasError'} [in C:\Users\aswal\deep_fake\app.py:50]
2024-10-03 15:26:54,412 INFO: Deepfake detection startup [in C:\Users\aswal\deep_fake\app.py:40]
2024-10-03 15:27:04,613 INFO: MongoDB connected successfully [in C:\Users\aswal\deep_fake\app.py:48]
2024-10-03 15:27:10,704 ERROR: Failed to load model: Unrecognized keyword arguments: ['batch_shape'] [in C:\Users\aswal\deep_fake\app.py:58]
2024-10-03 15:32:57,204 INFO: Deepfake detection startup [in C:\Users\aswal\deep_fake\app.py:42]
2024-10-03 15:33:04,703 INFO: MongoDB connected successfully [in C:\Users\aswal\deep_fake\app.py:50]
2024-10-03 15:33:06,904 ERROR: Failed to load model: Unrecognized keyword arguments: ['batch_shape'] [in C:\Users\aswal\deep_fake\app.py:61]
2024-10-03 15:39:03,610 INFO: Deepfake detection startup [in C:\Users\aswal\deep_fake\app.py:43]
2024-10-03 15:39:08,881 INFO: MongoDB connected successfully [in C:\Users\aswal\deep_fake\app.py:51]
2024-10-03 15:39:11,989 INFO: New model created and saved successfully [in C:\Users\aswal\deep_fake\app.py:63]
2024-10-03 15:39:12,420 INFO: Model loaded successfully [in C:\Users\aswal\deep_fake\app.py:72]
2024-10-03 15:42:21,630 ERROR: Error processing video: in user code:

    File "C:\Users\aswal\AppData\Local\Programs\Python\Python39\lib\site-packages\keras\engine\training.py", line 1845, in predict_function  *
        return step_function(self, iterator)
    File "C:\Users\aswal\AppData\Local\Programs\Python\Python39\lib\site-packages\keras\engine\training.py", line 1834, in step_function  **
        outputs = model.distribute_strategy.run(run_step, args=(data,))
    File "C:\Users\aswal\AppData\Local\Programs\Python\Python39\lib\site-packages\keras\engine\training.py", line 1823, in run_step  **
        outputs = model.predict_step(data)
    File "C:\Users\aswal\AppData\Local\Programs\Python\Python39\lib\site-packages\keras\engine\training.py", line 1791, in predict_step
        return self(x, training=False)
    File "C:\Users\aswal\AppData\Local\Programs\Python\Python39\lib\site-packages\keras\utils\traceback_utils.py", line 67, in error_handler
        raise e.with_traceback(filtered_tb) from None
    File "C:\Users\aswal\AppData\Local\Programs\Python\Python39\lib\site-packages\keras\engine\input_spec.py", line 264, in assert_input_compatibility
        raise ValueError(f'Input {input_index} of layer "{layer_name}" is '

    ValueError: Input 0 of layer "sequential" is incompatible with the layer: expected shape=(None, 64, 64, 3), found shape=(None, 224, 224, 3)
 [in C:\Users\aswal\deep_fake\app.py:121]
2024-10-03 15:42:21,634 ERROR: Error processing video: in user code:

    File "C:\Users\aswal\AppData\Local\Programs\Python\Python39\lib\site-packages\keras\engine\training.py", line 1845, in predict_function  *
        return step_function(self, iterator)
    File "C:\Users\aswal\AppData\Local\Programs\Python\Python39\lib\site-packages\keras\engine\training.py", line 1834, in step_function  **
        outputs = model.distribute_strategy.run(run_step, args=(data,))
    File "C:\Users\aswal\AppData\Local\Programs\Python\Python39\lib\site-packages\keras\engine\training.py", line 1823, in run_step  **
        outputs = model.predict_step(data)
    File "C:\Users\aswal\AppData\Local\Programs\Python\Python39\lib\site-packages\keras\engine\training.py", line 1791, in predict_step
        return self(x, training=False)
    File "C:\Users\aswal\AppData\Local\Programs\Python\Python39\lib\site-packages\keras\utils\traceback_utils.py", line 67, in error_handler
        raise e.with_traceback(filtered_tb) from None
    File "C:\Users\aswal\AppData\Local\Programs\Python\Python39\lib\site-packages\keras\engine\input_spec.py", line 264, in assert_input_compatibility
        raise ValueError(f'Input {input_index} of layer "{layer_name}" is '

    ValueError: Input 0 of layer "sequential" is incompatible with the layer: expected shape=(None, 64, 64, 3), found shape=(None, 224, 224, 3)
 [in C:\Users\aswal\deep_fake\app.py:121]
2024-10-03 15:42:21,638 ERROR: Error processing video: in user code:

    File "C:\Users\aswal\AppData\Local\Programs\Python\Python39\lib\site-packages\keras\engine\training.py", line 1845, in predict_function  *
        return step_function(self, iterator)
    File "C:\Users\aswal\AppData\Local\Programs\Python\Python39\lib\site-packages\keras\engine\training.py", line 1834, in step_function  **
        outputs = model.distribute_strategy.run(run_step, args=(data,))
    File "C:\Users\aswal\AppData\Local\Programs\Python\Python39\lib\site-packages\keras\engine\training.py", line 1823, in run_step  **
        outputs = model.predict_step(data)
    File "C:\Users\aswal\AppData\Local\Programs\Python\Python39\lib\site-packages\keras\engine\training.py", line 1791, in predict_step
        return self(x, training=False)
    File "C:\Users\aswal\AppData\Local\Programs\Python\Python39\lib\site-packages\keras\utils\traceback_utils.py", line 67, in error_handler
        raise e.with_traceback(filtered_tb) from None
    File "C:\Users\aswal\AppData\Local\Programs\Python\Python39\lib\site-packages\keras\engine\input_spec.py", line 264, in assert_input_compatibility
        raise ValueError(f'Input {input_index} of layer "{layer_name}" is '

    ValueError: Input 0 of layer "sequential" is incompatible with the layer: expected shape=(None, 64, 64, 3), found shape=(None, 224, 224, 3)
 [in C:\Users\aswal\deep_fake\app.py:121]
2024-10-03 15:42:21,641 ERROR: Error processing video: in user code:

    File "C:\Users\aswal\AppData\Local\Programs\Python\Python39\lib\site-packages\keras\engine\training.py", line 1845, in predict_function  *
        return step_function(self, iterator)
    File "C:\Users\aswal\AppData\Local\Programs\Python\Python39\lib\site-packages\keras\engine\training.py", line 1834, in step_function  **
        outputs = model.distribute_strategy.run(run_step, args=(data,))
    File "C:\Users\aswal\AppData\Local\Programs\Python\Python39\lib\site-packages\keras\engine\training.py", line 1823, in run_step  **
        outputs = model.predict_step(data)
    File "C:\Users\aswal\AppData\Local\Programs\Python\Python39\lib\site-packages\keras\engine\training.py", line 1791, in predict_step
        return self(x, training=False)
    File "C:\Users\aswal\AppData\Local\Programs\Python\Python39\lib\site-packages\keras\utils\traceback_utils.py", line 67, in error_handler
        raise e.with_traceback(filtered_tb) from None
    File "C:\Users\aswal\AppData\Local\Programs\Python\Python39\lib\site-packages\keras\engine\input_spec.py", line 264, in assert_input_compatibility
        raise ValueError(f'Input {input_index} of layer "{layer_name}" is '

    ValueError: Input 0 of layer "sequential" is incompatible with the layer: expected shape=(None, 64, 64, 3), found shape=(None, 224, 224, 3)
 [in C:\Users\aswal\deep_fake\app.py:121]
